Workbook

Sheet Simulasi Tanpa Take Over
A3: Simulasi KPR tanpa Take Over
A5: Biaya Plafon | B5: 2000000000
A6: Tenor (tahun) | B6: 20
A7: Masa Fix (tahun) | B7: 5
A8: Bunga Fix % | B8: 0.035
A9: Bunga Floating % | B9: 0.12
A10: Bunga Fix (Rp) | B10: ='KPR 1'!B6 -> 3.1848315e+08
A11: Bunga Floating (Rp) | B11: ='KPR 1'!B7 -> 1.8826274e+09
A12: Cicilan Bunga Fix | B12: ='KPR 1'!C10 -> 11599194
A13: Cicilan Bunga Floating | B13: ='KPR 1'!C70 -> 19473105
A14: Total Bunga | B14: =B10+B11 -> 2.2011105e+09

Sheet Simulasi Take Over
A3: Simulasi KPR Take Over Tahun ke 6-20
A5: Biaya Plafon | B5: 2000000000
A6: Tenor (tahun) | B6: 20
A7: Masa Fix (tahun) | B7: 5
A8: Bunga Fix % | B8: 0.035
A9: Bunga Fix (Rp) | B9: ='KPR 1'!B6 -> 3.1848315e+08
A10: Cicilan Bunga Fix | B10: ='KPR 1'!C10 -> 11599194
A11: Total Bunga | B11: =B9 -> 3.1848315e+08
A13: Perhitungan KPR Ke 2 Setelah Take Over
A14: Sisa Plafon | B14: ='KPR 1'!B5 -> 1.6225315e+09
A15: Tenor (tahun) | B15: 15
A16: Masa Fix (tahun) | B16: 5
A17: Bunga Fix % | B17: 0.0475
A18: Bunga Floating % | B18: 0.12
A19: Bunga Fix (Rp) | B19: ='KPR 2'!B6 -> 3.3840686e+08
A20: Bunga Floating (Rp) | B20: ='KPR 2'!B7 -> 8.6865486e+08
A21: Cicilan Bunga Fix | B21: ='KPR 2'!C10 -> 12620568
A22: Cicilan Bunga Floating | B22: ='KPR 2'!C70 -> 17269660
A23: Total Bunga | B23: =B19+B20 -> 1.2070617e+09
A25: Biaya Take Over
A26: Provisi | B26: 0.01 | C26: =$B$14*B26 -> 16225315
A27: Asuransi | B27: 0.01 | C27: =$B$14*B27 -> 16225315
A28: Pinalty | B28: 0.03 | C28: =$B$14*B28 -> 48675945
A29: Total Biaya Take Over | C29: =SUM(C26:C28) -> 81126575
A31: Rangkuman Biaya yang dikeluarkan
A32: Bunga KPR 1 (Fix Saja) | B32: =B11 -> 3.1848315e+08
A33: Bunga KPR 2 (Fix & Floating) | B33: =B23 -> 1.2070617e+09
A34: Biaya Take Over | B34: =C29 -> 81126575
A35: Total Bunga & Biaya Take Over | B35: =SUM(B32:B34) -> 1.6066715e+09
A37: Perbandingan biaya KPR tanpa Take Over dengan KPR Take Over
A38: Total Bunga tanpa Take Over | B38: ='Simulasi Tanpa Take Over'!B14 -> 2.2011105e+09
A39: Total Bunga dengan Take Over | B39: =B35 -> 1.6066715e+09
A40: Selisih | B40: =B38-B39 -> 5.9443907e+08
A41: Selisih (%) | B41: =B40/B38 -> 0.27006325
A43: Insight
A44: Dengan take over, bisa menghemat | B44: =B40 -> 5.9443907e+08
A45: Biaya yang dikeluarkan hanya biaya take over saja
A46: Note : masih dapat cashback asuransi dari KPR pertama
A47: Perbandingan cicilan saat pindah bank | B47: Bank 1 | C47: Bank 2
A48: Cicilan Bunga Fix | B48: ='Simulasi Tanpa Take Over'!B12 -> 11599194 | C48: =B21 -> 12620568
...

Sheet KPR 1
A1: Pokok | B1: 2000000000 | E1: Periode Bunga Fix | F1: 60 | G1: bulan
A2: Periode | B2: 240 | C2: bulan | E2: Periode Bunga Floating | F2: 180 | G2: bulan
A3: Bunga Fix | B3: 0.035
A4: Bunga Floating | B4: 0.12
A5: Sisa Pokok Setelah Bunga Fix | B5: =VLOOKUP(F1,$B$10:$D$69,3,0) -> 1.6225315e+09
A6: Total Bunga Fix | B6: =SUMIF(B10:B69,"<="&$F$1,$F$10:$F$69) -> 3.1848315e+08
A7: Total Bunga Floating | B7: =F9-B6 -> 1.8826274e+09
A8: Tahun | B8: Periode Angsuran | C8: Jumlah Angsuran | D8: Saldo Pokok | E8: Angsuran Pokok | F8: Angsuran Bunga
A9: Tahun 1 | B9: 0 | C9: =D9+F9 -> 4.2011105e+09 | D9: =$B$1 -> 2000000000 | E9: =$B$1 -> 2000000000 | F9: =SUMIF($B$10:$B$249,"<="&$B$2,$F$10:$F$249) -> 2.2011105e+09
B10: =B9+1 -> 1 | C10: =IF(AND($F$1<=$B$2,B10<=$F$1),($B$1*($B$3/12))/(1-1/(1+$B$3/12)^$B$2),($B$5*($B$4/12))/(1-1/(1+$B$4/12)^$F$2)) -> 11599194 | D10: =D9-E10 -> 1.9942341e+09 | E10: =C10-F10 -> 5765861 | F10: =IF(B10<=$F$1,D9*$B$3/12,D9*$B$4/12) -> 5833333.3
B11: =B10+1 -> 2 | C11: =IF(AND($F$1<=$B$2,B11<=$F$1),($B$1*($B$3/12))/(1-1/(1+$B$3/12)^$B$2),($B$5*($B$4/12))/(1-1/(1+$B$4/12)^$F$2)) -> 11599194 | D11: =D10-E11 -> 1.9884515e+09 | E11: =C11-F11 -> 5782678.1 | F11: =IF(B11<=$F$1,D10*$B$3/12,D10*$B$4/12) -> 5816516.2
B12: =B11+1 -> 3 | C12: =IF(AND($F$1<=$B$2,B12<=$F$1),($B$1*($B$3/12))/(1-1/(1+$B$3/12)^$B$2),($B$5*($B$4/12))/(1-1/(1+$B$4/12)^$F$2)) -> 11599194 | D12: =D11-E12 -> 1.9826519e+09 | E12: =C12-F12 -> 5799544.3 | F12: =IF(B12<=$F$1,D11*$B$3/12,D11*$B$4/12) -> 5799650.1
B13: =B12+1 -> 4 | C13: =IF(AND($F$1<=$B$2,B13<=$F$1),($B$1*($B$3/12))/(1-1/(1+$B$3/12)^$B$2),($B$5*($B$4/12))/(1-1/(1+$B$4/12)^$F$2)) -> 11599194 | D13: =D12-E13 -> 1.9768355e+09 | E13: =C13-F13 -> 5816459.6 | F13: =IF(B13<=$F$1,D12*$B$3/12,D12*$B$4/12) -> 5782734.8
B14: =B13+1 -> 5 | C14: =IF(AND($F$1<=$B$2,B14<=$F$1),($B$1*($B$3/12))/(1-1/(1+$B$3/12)^$B$2),($B$5*($B$4/12))/(1-1/(1+$B$4/12)^$F$2)) -> 11599194 | D14: =D13-E14 -> 1.971002e+09 | E14: =C14-F14 -> 5833424.3 | F14: =IF(B14<=$F$1,D13*$B$3/12,D13*$B$4/12) -> 5765770.1
B15: =B14+1 -> 6 | C15: =IF(AND($F$1<=$B$2,B15<=$F$1),($B$1*($B$3/12))/(1-1/(1+$B$3/12)^$B$2),($B$5*($B$4/12))/(1-1/(1+$B$4/12)^$F$2)) -> 11599194 | D15: =D14-E15 -> 1.9651516e+09 | E15: =C15-F15 -> 5850438.4 | F15: =IF(B15<=$F$1,D14*$B$3/12,D14*$B$4/12) -> 5748755.9
B16: =B15+1 -> 7 | C16: =IF(AND($F$1<=$B$2,B16<=$F$1),($B$1*($B$3/12))/(1-1/(1+$B$3/12)^$B$2),($B$5*($B$4/12))/(1-1/(1+$B$4/12)^$F$2)) -> 11599194 | D16: =D15-E16 -> 1.9592841e+09 | E16: =C16-F16 -> 5867502.2 | F16: =IF(B16<=$F$1,D15*$B$3/12,D15*$B$4/12) -> 5731692.1
B17: =B16+1 -> 8 | C17: =IF(AND($F$1<=$B$2,B17<=$F$1),($B$1*($B$3/12))/(1-1/(1+$B$3/12)^$B$2),($B$5*($B$4/12))/(1-1/(1+$B$4/12)^$F$2)) -> 11599194 | D17: =D16-E17 -> 1.9533995e+09 | E17: =C17-F17 -> 5884615.8 | F17: =IF(B17<=$F$1,D16*$B$3/12,D16*$B$4/12) -> 5714578.6
B18: =B17+1 -> 9 | C18: =IF(AND($F$1<=$B$2,B18<=$F$1),($B$1*($B$3/12))/(1-1/(1+$B$3/12)^$B$2),($B$5*($B$4/12))/(1-1/(1+$B$4/12)^$F$2)) -> 11599194 | D18: =D17-E18 -> 1.9474977e+09 | E18: =C18-F18 -> 5901779.2 | F18: =IF(B18<=$F$1,D17*$B$3/12,D17*$B$4/12) -> 5697415.1
B19: =B18+1 -> 10 | C19: =IF(AND($F$1<=$B$2,B19<=$F$1),($B$1*($B$3/12))/(1-1/(1+$B$3/12)^$B$2),($B$5*($B$4/12))/(1-1/(1+$B$4/12)^$F$2)) -> 11599194 | D19: =D18-E19 -> 1.9415787e+09 | E19: =C19-F19 -> 5918992.7 | F19: =IF(B19<=$F$1,D18*$B$3/12,D18*$B$4/12) -> 5680201.6
B20: =B19+1 -> 11 | C20: =IF(AND($F$1<=$B$2,B20<=$F$1),($B$1*($B$3/12))/(1-1/(1+$B$3/12)^$B$2),($B$5*($B$4/12))/(1-1/(1+$B$4/12)^$F$2)) -> 11599194 | D20: =D19-E20 -> 1.9356424e+09 | E20: =C20-F20 -> 5936256.5 | F20: =IF(B20<=$F$1,D19*$B$3/12,D19*$B$4/12) -> 5662937.9
B21: =B20+1 -> 12 | C21: =IF(AND($F$1<=$B$2,B21<=$F$1),($B$1*($B$3/12))/(1-1/(1+$B$3/12)^$B$2),($B$5*($B$4/12))/(1-1/(1+$B$4/12)^$F$2)) -> 11599194 | D21: =D20-E21 -> 1.9296889e+09 | E21: =C21-F21 -> 5953570.6 | F21: =IF(B21<=$F$1,D20*$B$3/12,D20*$B$4/12) -> 5645623.8
A22: Tahun 2 | B22: =B21+1 -> 13 | C22: =IF(AND($F$1<=$B$2,B22<=$F$1),($B$1*($B$3/12))/(1-1/(1+$B$3/12)^$B$2),($B$5*($B$4/12))/(1-1/(1+$B$4/12)^$F$2)) -> 11599194 | D22: =D21-E22 -> 1.9237179e+09 | E22: =C22-F22 -> 5970935.1 | F22: =IF(B22<=$F$1,D21*$B$3/12,D21*$B$4/12) -> 5628259.2
B23: =B22+1 -> 14 | C23: =IF(AND($F$1<=$B$2,B23<=$F$1),($B$1*($B$3/12))/(1-1/(1+$B$3/12)^$B$2),($B$5*($B$4/12))/(1-1/(1+$B$4/12)^$F$2)) -> 11599194 | D23: =D22-E23 -> 1.9177296e+09 | E23: =C23-F23 -> 5988350.4 | F23: =IF(B23<=$F$1,D22*$B$3/12,D22*$B$4/12) -> 5610844
B24: =B23+1 -> 15 | C24: =IF(AND($F$1<=$B$2,B24<=$F$1),($B$1*($B$3/12))/(1-1/(1+$B$3/12)^$B$2),($B$5*($B$4/12))/(1-1/(1+$B$4/12)^$F$2)) -> 11599194 | D24: =D23-E24 -> 1.9117238e+09 | E24: =C24-F24 -> 6005816.4 | F24: =IF(B24<=$F$1,D23*$B$3/12,D23*$B$4/12) -> 5593378
B25: =B24+1 -> 16 | C25: =IF(AND($F$1<=$B$2,B25<=$F$1),($B$1*($B$3/12))/(1-1/(1+$B$3/12)^$B$2),($B$5*($B$4/12))/(1-1/(1+$B$4/12)^$F$2)) -> 11599194 | D25: =D24-E25 -> 1.9057004e+09 | E25: =C25-F25 -> 6023333.3 | F25: =IF(B25<=$F$1,D24*$B$3/12,D24*$B$4/12) -> 5575861
B26: =B25+1 -> 17 | C26: =IF(AND($F$1<=$B$2,B26<=$F$1),($B$1*($B$3/12))/(1-1/(1+$B$3/12)^$B$2),($B$5*($B$4/12))/(1-1/(1+$B$4/12)^$F$2)) -> 11599194 | D26: =D25-E26 -> 1.8996595e+09 | E26: =C26-F26 -> 6040901.4 | F26: =IF(B26<=$F$1,D25*$B$3/12,D25*$B$4/12) -> 5558293
B27: =B26+1 -> 18 | C27: =IF(AND($F$1<=$B$2,B27<=$F$1),($B$1*($B$3/12))/(1-1/(1+$B$3/12)^$B$2),($B$5*($B$4/12))/(1-1/(1+$B$4/12)^$F$2)) -> 11599194 | D27: =D26-E27 -> 1.893601e+09 | E27: =C27-F27 -> 6058520.7 | F27: =IF(B27<=$F$1,D26*$B$3/12,D26*$B$4/12) -> 5540673.7
B28: =B27+1 -> 19 | C28: =IF(AND($F$1<=$B$2,B28<=$F$1),($B$1*($B$3/12))/(1-1/(1+$B$3/12)^$B$2),($B$5*($B$4/12))/(1-1/(1+$B$4/12)^$F$2)) -> 11599194 | D28: =D27-E28 -> 1.8875248e+09 | E28: =C28-F28 -> 6076191.4 | F28: =IF(B28<=$F$1,D27*$B$3/12,D27*$B$4/12) -> 5523003
B29: =B28+1 -> 20 | C29: =IF(AND($F$1<=$B$2,B29<=$F$1),($B$1*($B$3/12))/(1-1/(1+$B$3/12)^$B$2),($B$5*($B$4/12))/(1-1/(1+$B$4/12)^$F$2)) -> 11599194 | D29: =D28-E29 -> 1.8814309e+09 | E29: =C29-F29 -> 6093913.6 | F29: =IF(B29<=$F$1,D28*$B$3/12,D28*$B$4/12) -> 5505280.8
B30: =B29+1 -> 21 | C30: =IF(AND($F$1<=$B$2,B30<=$F$1),($B$1*($B$3/12))/(1-1/(1+$B$3/12)^$B$2),($B$5*($B$4/12))/(1-1/(1+$B$4/12)^$F$2)) -> 11599194 | D30: =D29-E30 -> 1.8753192e+09 | E30: =C30-F30 -> 6111687.5 | F30: =IF(B30<=$F$1,D29*$B$3/12,D29*$B$4/12) -> 5487506.8
B31: =B30+1 -> 22 | C31: =IF(AND($F$1<=$B$2,B31<=$F$1),($B$1*($B$3/12))/(1-1/(1+$B$3/12)^$B$2),($B$5*($B$4/12))/(1-1/(1+$B$4/12)^$F$2)) -> 11599194 | D31: =D30-E31 -> 1.8691897e+09 | E31: =C31-F31 -> 6129513.3 | F31: =IF(B31<=$F$1,D30*$B$3/12,D30*$B$4/12) -> 5469681.1
B32: =B31+1 -> 23 | C32: =IF(AND($F$1<=$B$2,B32<=$F$1),($B$1*($B$3/12))/(1-1/(1+$B$3/12)^$B$2),($B$5*($B$4/12))/(1-1/(1+$B$4/12)^$F$2)) -> 11599194 | D32: =D31-E32 -> 1.8630423e+09 | E32: =C32-F32 -> 6147391 | F32: =IF(B32<=$F$1,D31*$B$3/12,D31*$B$4/12) -> 5451803.3
B33: =B32+1 -> 24 | C33: =IF(AND($F$1<=$B$2,B33<=$F$1),($B$1*($B$3/12))/(1-1/(1+$B$3/12)^$B$2),($B$5*($B$4/12))/(1-1/(1+$B$4/12)^$F$2)) -> 11599194 | D33: =D32-E33 -> 1.856877e+09 | E33: =C33-F33 -> 6165320.9 | F33: =IF(B33<=$F$1,D32*$B$3/12,D32*$B$4/12) -> 5433873.4
A34: Tahun 3 | B34: =B33+1 -> 25 | C34: =IF(AND($F$1<=$B$2,B34<=$F$1),($B$1*($B$3/12))/(1-1/(1+$B$3/12)^$B$2),($B$5*($B$4/12))/(1-1/(1+$B$4/12)^$F$2)) -> 11599194 | D34: =D33-E34 -> 1.8506937e+09 | E34: =C34-F34 -> 6183303.1 | F34: =IF(B34<=$F$1,D33*$B$3/12,D33*$B$4/12) -> 5415891.3
B35: =B34+1 -> 26 | C35: =IF(AND($F$1<=$B$2,B35<=$F$1),($B$1*($B$3/12))/(1-1/(1+$B$3/12)^$B$2),($B$5*($B$4/12))/(1-1/(1+$B$4/12)^$F$2)) -> 11599194 | D35: =D34-E35 -> 1.8444924e+09 | E35: =C35-F35 -> 6201337.7 | F35: =IF(B35<=$F$1,D34*$B$3/12,D34*$B$4/12) -> 5397856.6
B36: =B35+1 -> 27 | C36: =IF(AND($F$1<=$B$2,B36<=$F$1),($B$1*($B$3/12))/(1-1/(1+$B$3/12)^$B$2),($B$5*($B$4/12))/(1-1/(1+$B$4/12)^$F$2)) -> 11599194 | D36: =D35-E36 -> 1.8382729e+09 | E36: =C36-F36 -> 6219425 | F36: =IF(B36<=$F$1,D35*$B$3/12,D35*$B$4/12) -> 5379769.4
B37: =B36+1 -> 28 | C37: =IF(AND($F$1<=$B$2,B37<=$F$1),($B$1*($B$3/12))/(1-1/(1+$B$3/12)^$B$2),($B$5*($B$4/12))/(1-1/(1+$B$4/12)^$F$2)) -> 11599194 | D37: =D36-E37 -> 1.8320354e+09 | E37: =C37-F37 -> 6237565 | F37: =IF(B37<=$F$1,D36*$B$3/12,D36*$B$4/12) -> 5361629.4
B38: =B37+1 -> 29 | C38: =IF(AND($F$1<=$B$2,B38<=$F$1),($B$1*($B$3/12))/(1-1/(1+$B$3/12)^$B$2),($B$5*($B$4/12))/(1-1/(1+$B$4/12)^$F$2)) -> 11599194 | D38: =D37-E38 -> 1.8257796e+09 | E38: =C38-F38 -> 6255757.9 | F38: =IF(B38<=$F$1,D37*$B$3/12,D37*$B$4/12) -> 5343436.5
B39: =B38+1 -> 30 | C39: =IF(AND($F$1<=$B$2,B39<=$F$1),($B$1*($B$3/12))/(1-1/(1+$B$3/12)^$B$2),($B$5*($B$4/12))/(1-1/(1+$B$4/12)^$F$2)) -> 11599194 | D39: =D38-E39 -> 1.8195056e+09 | E39: =C39-F39 -> 6274003.8 | F39: =IF(B39<=$F$1,D38*$B$3/12,D38*$B$4/12) -> 5325190.5
B40: =B39+1 -> 31 | C40: =IF(AND($F$1<=$B$2,B40<=$F$1),($B$1*($B$3/12))/(1-1/(1+$B$3/12)^$B$2),($B$5*($B$4/12))/(1-1/(1+$B$4/12)^$F$2)) -> 11599194 | D40: =D39-E40 -> 1.8132133e+09 | E40: =C40-F40 -> 6292303 | F40: =IF(B40<=$F$1,D39*$B$3/12,D39*$B$4/12) -> 5306891.4
...

Sheet KPR 2
A1: Pokok | B1: 1622531491 | E1: Periode Bunga Fix | F1: 60 | G1: bulan
A2: Periode | B2: 180 | C2: bulan | E2: Periode Bunga Floating | F2: 120 | G2: bulan
A3: Bunga Fix | B3: 0.0475
A4: Bunga Floating | B4: 0.12
A5: Sisa Pokok Setelah Bunga Fix | B5: =VLOOKUP(F1,$B$10:$D$69,3,0) -> 1.2037043e+09
A6: Total Bunga Fix | B6: =SUMIF(B10:B69,"<="&$F$1,$F$10:$F$69) -> 3.3840686e+08
A7: Total Bunga Floating | B7: =F9-B6 -> 8.6865486e+08
A8: Tahun | B8: Periode Angsuran | C8: Jumlah Angsuran | D8: Saldo Pokok | E8: Angsuran Pokok | F8: Angsuran Bunga
A9: Tahun 1 | B9: 0 | C9: =D9+F9 -> 2.8295932e+09 | D9: =$B$1 -> 1622531491 | E9: =$B$1 -> 1622531491 | F9: =SUMIF($B$10:$B$189,"<="&$B$2,$F$10:$F$189) -> 1.2070617e+09
B10: =B9+1 -> 1 | C10: =IF(AND($F$1<=$B$2,B10<=$F$1),($B$1*($B$3/12))/(1-1/(1+$B$3/12)^$B$2),($B$5*($B$4/12))/(1-1/(1+$B$4/12)^$F$2)) -> 12620568 | D10: =D9-E10 -> 1.6163334e+09 | E10: =C10-F10 -> 6198047.3 | F10: =IF(B10<=$F$1,D9*$B$3/12,D9*$B$4/12) -> 6422520.5
B11: =B10+1 -> 2 | C11: =IF(AND($F$1<=$B$2,B11<=$F$1),($B$1*($B$3/12))/(1-1/(1+$B$3/12)^$B$2),($B$5*($B$4/12))/(1-1/(1+$B$4/12)^$F$2)) -> 12620568 | D11: =D10-E11 -> 1.6101109e+09 | E11: =C11-F11 -> 6222581.3 | F11: =IF(B11<=$F$1,D10*$B$3/12,D10*$B$4/12) -> 6397986.5
B12: =B11+1 -> 3 | C12: =IF(AND($F$1<=$B$2,B12<=$F$1),($B$1*($B$3/12))/(1-1/(1+$B$3/12)^$B$2),($B$5*($B$4/12))/(1-1/(1+$B$4/12)^$F$2)) -> 12620568 | D12: =D11-E12 -> 1.6038637e+09 | E12: =C12-F12 -> 6247212.3 | F12: =IF(B12<=$F$1,D11*$B$3/12,D11*$B$4/12) -> 6373355.5
B13: =B12+1 -> 4 | C13: =IF(AND($F$1<=$B$2,B13<=$F$1),($B$1*($B$3/12))/(1-1/(1+$B$3/12)^$B$2),($B$5*($B$4/12))/(1-1/(1+$B$4/12)^$F$2)) -> 12620568 | D13: =D12-E13 -> 1.5975917e+09 | E13: =C13-F13 -> 6271940.9 | F13: =IF(B13<=$F$1,D12*$B$3/12,D12*$B$4/12) -> 6348626.9
B14: =B13+1 -> 5 | C14: =IF(AND($F$1<=$B$2,B14<=$F$1),($B$1*($B$3/12))/(1-1/(1+$B$3/12)^$B$2),($B$5*($B$4/12))/(1-1/(1+$B$4/12)^$F$2)) -> 12620568 | D14: =D13-E14 -> 1.5912949e+09 | E14: =C14-F14 -> 6296767.3 | F14: =IF(B14<=$F$1,D13*$B$3/12,D13*$B$4/12) -> 6323800.5
B15: =B14+1 -> 6 | C15: =IF(AND($F$1<=$B$2,B15<=$F$1),($B$1*($B$3/12))/(1-1/(1+$B$3/12)^$B$2),($B$5*($B$4/12))/(1-1/(1+$B$4/12)^$F$2)) -> 12620568 | D15: =D14-E15 -> 1.5849732e+09 | E15: =C15-F15 -> 6321692 | F15: =IF(B15<=$F$1,D14*$B$3/12,D14*$B$4/12) -> 6298875.8
B16: =B15+1 -> 7 | C16: =IF(AND($F$1<=$B$2,B16<=$F$1),($B$1*($B$3/12))/(1-1/(1+$B$3/12)^$B$2),($B$5*($B$4/12))/(1-1/(1+$B$4/12)^$F$2)) -> 12620568 | D16: =D15-E16 -> 1.5786265e+09 | E16: =C16-F16 -> 6346715.4 | F16: =IF(B16<=$F$1,D15*$B$3/12,D15*$B$4/12) -> 6273852.4
B17: =B16+1 -> 8 | C17: =IF(AND($F$1<=$B$2,B17<=$F$1),($B$1*($B$3/12))/(1-1/(1+$B$3/12)^$B$2),($B$5*($B$4/12))/(1-1/(1+$B$4/12)^$F$2)) -> 12620568 | D17: =D16-E17 -> 1.5722547e+09 | E17: =C17-F17 -> 6371837.8 | F17: =IF(B17<=$F$1,D16*$B$3/12,D16*$B$4/12) -> 6248730
B18: =B17+1 -> 9 | C18: =IF(AND($F$1<=$B$2,B18<=$F$1),($B$1*($B$3/12))/(1-1/(1+$B$3/12)^$B$2),($B$5*($B$4/12))/(1-1/(1+$B$4/12)^$F$2)) -> 12620568 | D18: =D17-E18 -> 1.5658576e+09 | E18: =C18-F18 -> 6397059.6 | F18: =IF(B18<=$F$1,D17*$B$3/12,D17*$B$4/12) -> 6223508.2
B19: =B18+1 -> 10 | C19: =IF(AND($F$1<=$B$2,B19<=$F$1),($B$1*($B$3/12))/(1-1/(1+$B$3/12)^$B$2),($B$5*($B$4/12))/(1-1/(1+$B$4/12)^$F$2)) -> 12620568 | D19: =D18-E19 -> 1.5594353e+09 | E19: =C19-F19 -> 6422381.3 | F19: =IF(B19<=$F$1,D18*$B$3/12,D18*$B$4/12) -> 6198186.5
B20: =B19+1 -> 11 | C20: =IF(AND($F$1<=$B$2,B20<=$F$1),($B$1*($B$3/12))/(1-1/(1+$B$3/12)^$B$2),($B$5*($B$4/12))/(1-1/(1+$B$4/12)^$F$2)) -> 12620568 | D20: =D19-E20 -> 1.5529875e+09 | E20: =C20-F20 -> 6447803.3 | F20: =IF(B20<=$F$1,D19*$B$3/12,D19*$B$4/12) -> 6172764.6
B21: =B20+1 -> 12 | C21: =IF(AND($F$1<=$B$2,B21<=$F$1),($B$1*($B$3/12))/(1-1/(1+$B$3/12)^$B$2),($B$5*($B$4/12))/(1-1/(1+$B$4/12)^$F$2)) -> 12620568 | D21: =D20-E21 -> 1.5465141e+09 | E21: =C21-F21 -> 6473325.8 | F21: =IF(B21<=$F$1,D20*$B$3/12,D20*$B$4/12) -> 6147242
A22: Tahun 2 | B22: =B21+1 -> 13 | C22: =IF(AND($F$1<=$B$2,B22<=$F$1),($B$1*($B$3/12))/(1-1/(1+$B$3/12)^$B$2),($B$5*($B$4/12))/(1-1/(1+$B$4/12)^$F$2)) -> 12620568 | D22: =D21-E22 -> 1.5400152e+09 | E22: =C22-F22 -> 6498949.4 | F22: =IF(B22<=$F$1,D21*$B$3/12,D21*$B$4/12) -> 6121618.4
B23: =B22+1 -> 14 | C23: =IF(AND($F$1<=$B$2,B23<=$F$1),($B$1*($B$3/12))/(1-1/(1+$B$3/12)^$B$2),($B$5*($B$4/12))/(1-1/(1+$B$4/12)^$F$2)) -> 12620568 | D23: =D22-E23 -> 1.5334905e+09 | E23: =C23-F23 -> 6524674.4 | F23: =IF(B23<=$F$1,D22*$B$3/12,D22*$B$4/12) -> 6095893.4
B24: =B23+1 -> 15 | C24: =IF(AND($F$1<=$B$2,B24<=$F$1),($B$1*($B$3/12))/(1-1/(1+$B$3/12)^$B$2),($B$5*($B$4/12))/(1-1/(1+$B$4/12)^$F$2)) -> 12620568 | D24: =D23-E24 -> 1.52694e+09 | E24: =C24-F24 -> 6550501.2 | F24: =IF(B24<=$F$1,D23*$B$3/12,D23*$B$4/12) -> 6070066.6
B25: =B24+1 -> 16 | C25: =IF(AND($F$1<=$B$2,B25<=$F$1),($B$1*($B$3/12))/(1-1/(1+$B$3/12)^$B$2),($B$5*($B$4/12))/(1-1/(1+$B$4/12)^$F$2)) -> 12620568 | D25: =D24-E25 -> 1.5203636e+09 | E25: =C25-F25 -> 6576430.3 | F25: =IF(B25<=$F$1,D24*$B$3/12,D24*$B$4/12) -> 6044137.5
B26: =B25+1 -> 17 | C26: =IF(AND($F$1<=$B$2,B26<=$F$1),($B$1*($B$3/12))/(1-1/(1+$B$3/12)^$B$2),($B$5*($B$4/12))/(1-1/(1+$B$4/12)^$F$2)) -> 12620568 | D26: =D25-E26 -> 1.5137611e+09 | E26: =C26-F26 -> 6602462 | F26: =IF(B26<=$F$1,D25*$B$3/12,D25*$B$4/12) -> 6018105.8
B27: =B26+1 -> 18 | C27: =IF(AND($F$1<=$B$2,B27<=$F$1),($B$1*($B$3/12))/(1-1/(1+$B$3/12)^$B$2),($B$5*($B$4/12))/(1-1/(1+$B$4/12)^$F$2)) -> 12620568 | D27: =D26-E27 -> 1.5071325e+09 | E27: =C27-F27 -> 6628596.8 | F27: =IF(B27<=$F$1,D26*$B$3/12,D26*$B$4/12) -> 5991971.1
B28: =B27+1 -> 19 | C28: =IF(AND($F$1<=$B$2,B28<=$F$1),($B$1*($B$3/12))/(1-1/(1+$B$3/12)^$B$2),($B$5*($B$4/12))/(1-1/(1+$B$4/12)^$F$2)) -> 12620568 | D28: =D27-E28 -> 1.5004777e+09 | E28: =C28-F28 -> 6654834.9 | F28: =IF(B28<=$F$1,D27*$B$3/12,D27*$B$4/12) -> 5965732.9
B29: =B28+1 -> 20 | C29: =IF(AND($F$1<=$B$2,B29<=$F$1),($B$1*($B$3/12))/(1-1/(1+$B$3/12)^$B$2),($B$5*($B$4/12))/(1-1/(1+$B$4/12)^$F$2)) -> 12620568 | D29: =D28-E29 -> 1.4937965e+09 | E29: =C29-F29 -> 6681177 | F29: =IF(B29<=$F$1,D28*$B$3/12,D28*$B$4/12) -> 5939390.8
B30: =B29+1 -> 21 | C30: =IF(AND($F$1<=$B$2,B30<=$F$1),($B$1*($B$3/12))/(1-1/(1+$B$3/12)^$B$2),($B$5*($B$4/12))/(1-1/(1+$B$4/12)^$F$2)) -> 12620568 | D30: =D29-E30 -> 1.4870889e+09 | E30: =C30-F30 -> 6707623.3 | F30: =IF(B30<=$F$1,D29*$B$3/12,D29*$B$4/12) -> 5912944.5
B31: =B30+1 -> 22 | C31: =IF(AND($F$1<=$B$2,B31<=$F$1),($B$1*($B$3/12))/(1-1/(1+$B$3/12)^$B$2),($B$5*($B$4/12))/(1-1/(1+$B$4/12)^$F$2)) -> 12620568 | D31: =D30-E31 -> 1.4803547e+09 | E31: =C31-F31 -> 6734174.3 | F31: =IF(B31<=$F$1,D30*$B$3/12,D30*$B$4/12) -> 5886393.5
B32: =B31+1 -> 23 | C32: =IF(AND($F$1<=$B$2,B32<=$F$1),($B$1*($B$3/12))/(1-1/(1+$B$3/12)^$B$2),($B$5*($B$4/12))/(1-1/(1+$B$4/12)^$F$2)) -> 12620568 | D32: =D31-E32 -> 1.4735939e+09 | E32: =C32-F32 -> 6760830.4 | F32: =IF(B32<=$F$1,D31*$B$3/12,D31*$B$4/12) -> 5859737.4
B33: =B32+1 -> 24 | C33: =IF(AND($F$1<=$B$2,B33<=$F$1),($B$1*($B$3/12))/(1-1/(1+$B$3/12)^$B$2),($B$5*($B$4/12))/(1-1/(1+$B$4/12)^$F$2)) -> 12620568 | D33: =D32-E33 -> 1.4668063e+09 | E33: =C33-F33 -> 6787592.1 | F33: =IF(B33<=$F$1,D32*$B$3/12,D32*$B$4/12) -> 5832975.7
A34: Tahun 3 | B34: =B33+1 -> 25 | C34: =IF(AND($F$1<=$B$2,B34<=$F$1),($B$1*($B$3/12))/(1-1/(1+$B$3/12)^$B$2),($B$5*($B$4/12))/(1-1/(1+$B$4/12)^$F$2)) -> 12620568 | D34: =D33-E34 -> 1.4599918e+09 | E34: =C34-F34 -> 6814459.6 | F34: =IF(B34<=$F$1,D33*$B$3/12,D33*$B$4/12) -> 5806108.2
B35: =B34+1 -> 26 | C35: =IF(AND($F$1<=$B$2,B35<=$F$1),($B$1*($B$3/12))/(1-1/(1+$B$3/12)^$B$2),($B$5*($B$4/12))/(1-1/(1+$B$4/12)^$F$2)) -> 12620568 | D35: =D34-E35 -> 1.4531504e+09 | E35: =C35-F35 -> 6841433.5 | F35: =IF(B35<=$F$1,D34*$B$3/12,D34*$B$4/12) -> 5779134.3
B36: =B35+1 -> 27 | C36: =IF(AND($F$1<=$B$2,B36<=$F$1),($B$1*($B$3/12))/(1-1/(1+$B$3/12)^$B$2),($B$5*($B$4/12))/(1-1/(1+$B$4/12)^$F$2)) -> 12620568 | D36: =D35-E36 -> 1.4462819e+09 | E36: =C36-F36 -> 6868514.2 | F36: =IF(B36<=$F$1,D35*$B$3/12,D35*$B$4/12) -> 5752053.6
B37: =B36+1 -> 28 | C37: =IF(AND($F$1<=$B$2,B37<=$F$1),($B$1*($B$3/12))/(1-1/(1+$B$3/12)^$B$2),($B$5*($B$4/12))/(1-1/(1+$B$4/12)^$F$2)) -> 12620568 | D37: =D36-E37 -> 1.4393862e+09 | E37: =C37-F37 -> 6895702.1 | F37: =IF(B37<=$F$1,D36*$B$3/12,D36*$B$4/12) -> 5724865.7
B38: =B37+1 -> 29 | C38: =IF(AND($F$1<=$B$2,B38<=$F$1),($B$1*($B$3/12))/(1-1/(1+$B$3/12)^$B$2),($B$5*($B$4/12))/(1-1/(1+$B$4/12)^$F$2)) -> 12620568 | D38: =D37-E38 -> 1.4324632e+09 | E38: =C38-F38 -> 6922997.6 | F38: =IF(B38<=$F$1,D37*$B$3/12,D37*$B$4/12) -> 5697570.3
B39: =B38+1 -> 30 | C39: =IF(AND($F$1<=$B$2,B39<=$F$1),($B$1*($B$3/12))/(1-1/(1+$B$3/12)^$B$2),($B$5*($B$4/12))/(1-1/(1+$B$4/12)^$F$2)) -> 12620568 | D39: =D38-E39 -> 1.4255128e+09 | E39: =C39-F39 -> 6950401.1 | F39: =IF(B39<=$F$1,D38*$B$3/12,D38*$B$4/12) -> 5670166.7
B40: =B39+1 -> 31 | C40: =IF(AND($F$1<=$B$2,B40<=$F$1),($B$1*($B$3/12))/(1-1/(1+$B$3/12)^$B$2),($B$5*($B$4/12))/(1-1/(1+$B$4/12)^$F$2)) -> 12620568 | D40: =D39-E40 -> 1.4185349e+09 | E40: =C40-F40 -> 6977913.1 | F40: =IF(B40<=$F$1,D39*$B$3/12,D39*$B$4/12) -> 5642654.7
...
